Workbook

Sheet main-data
B1: Year | C1: Code | D1: Company Name | E1: SIC-2 | F1: Sub Sector | G1: Current’s shares price | H1: Investment | I1: Fixed Assets | J1: Total Assets | K1: Long-Term Liabilities | L1: Total Liabilities | M1: Total Equity | N1: Total outstanding shares | O1: Total Sales/ Revenue | P1: COGS/ Cost of Revenues | Q1: delta sales | R1: delta COGS | S1: ITSE | T1: Expenses (Income) | U1: Net Income | V1: PBV | W1: DAR | X1: DER | Y1: ROA | Z1: ROE | AA1: OPM | AB1: NPM | AC1: ROS | AD1: TI Investment - Hardware | AE1: TI Investment - Software | AF1: Pertamakali/ lanjutan | AG1: TI Investment - Networking | AH1: TI Investment - Datastorage | AI1: TI Investment - License | AJ1: TI Investment - Others | AK1: IT Expenditure | AL1: R&D Expenditures | AM1: Advertising Expenditures
A2: 280 | B2: 2018 | C2: LINK | D2: Link Net Tbk | E2: 9.4 | F2: Sub Sektor Advertising Printing dan Media | I2: 4568443000000 | J2: 6023611000000 | K2: 176933000000 | L2: 1272512000000 | M2: 4751099000000 | N2: 8040000000 | O2: 3728364000000 | P2: 744797000000 | T2: =222697000000+869579000000+59597000000 -> 1151873000000 | U2: 788918000000 | V2: =M2 -> 4751099000000 | W2: =L2/J2 -> 0.21125401 | X2: =L2/M2 -> 0.26783529 | Y2: =U2/J2 -> 0.13097094 | Z2: =U2/M2 -> 0.16604958 | AA2: =(O2-P2)/O2 -> 0.8002349 | AB2: =U2/O2 -> 0.21159897 | AC2: =AA2 -> 0.8002349
A3: 281 | B3: 2019 | C3: LINK | D3: Link Net Tbk | E3: 9.4 | F3: Sub Sektor Advertising Printing dan Media | I3: 4993913000000 | J3: 6652974000000 | K3: 183236000000 | L3: 1996559000000 | M3: 4656415000000 | N3: 8040000000 | O3: 3755262000000 | P3: 747703000000 | T3: =301334000000+528656000000+11231000000 -> 841221000000 | U3: 894531000000 | V3: =M3 -> 4656415000000 | W3: =L3/J3 -> 0.30010023 | X3: =L3/M3 -> 0.428776 | Y3: =U3/J3 -> 0.13445581 | Z3: =U3/M3 -> 0.19210723 | AA3: =(O3-P3)/O3 -> 0.80089192 | AB3: =U3/O3 -> 0.23820735 | AC3: =AA3 -> 0.80089192
A4: 282 | B4: 2020 | C4: LINK | D4: Link Net Tbk | E4: 9.4 | F4: Sub Sektor Advertising Printing dan Media | I4: 5641224000000 | J4: 7799803000000 | K4: 359078000000 | L4: 3177089800000 | M4: 7799803000000 | N4: 8040000000 | O4: 4047964000000 | P4: 868743000000 | T4: =364242000000+505765000000+8171000000 -> 878178000000 | U4: 941707000000 | V4: =M4 -> 7799803000000 | W4: =L4/J4 -> 0.40732949 | X4: =L4/M4 -> 0.40732949 | Y4: =U4/J4 -> 0.12073472 | Z4: =U4/M4 -> 0.12073472 | AA4: =(O4-P4)/O4 -> 0.78538767 | AB4: =U4/O4 -> 0.2326372 | AC4: =AA4 -> 0.78538767
A5: 328 | B5: 2018 | C5: MNCN | D5: Media Nusantara Citra Tbk | E5: 9.4 | F5: Sub Sektor Advertising Printing dan Media | H5: 10065000000 | I5: 5541768000000 | J5: 16339552000000 | K5: 3543528000000 | L5: 5697247000000 | M5: 10642305000000 | N5: =5700000000+34300000000 -> 40000000000 | O5: 7443905000000 | P5: 2825002000000 | T5: =1879140000000+13176000000 -> 1892316000000 | U5: 1605621000000 | V5: =M5 -> 10642305000000 | W5: =L5/J5 -> 0.34867829 | X5: =L5/M5 -> 0.53533957 | Y5: =U5/J5 -> 0.098265913 | Z5: =U5/M5 -> 0.15087155 | AA5: =(O5-P5)/O5 -> 0.62049462 | AB5: =U5/O5 -> 0.21569606 | AC5: =AA5 -> 0.62049462
A6: 329 | B6: 2019 | C6: MNCN | D6: Media Nusantara Citra Tbk | E6: 9.4 | F6: Sub Sektor Advertising Printing dan Media | H6: 196065000000 | I6: 5682365000000 | J6: 17836430000000 | K6: 3171441000000 | L6: 5310928000000 | M6: 12525502000000 | N6: =5700000000+34300000000 -> 40000000000 | O6: 8353365000000 | P6: 3030488000000 | T6: =2063877000000+20378000000 -> 2084255000000 | U6: 2352529000000 | V6: =M6 -> 12525502000000 | W6: =L6/J6 -> 0.29775734 | X6: =L6/M6 -> 0.42400919 | Y6: =U6/J6 -> 0.13189461 | Z6: =U6/M6 -> 0.18781914 | AA6: =(O6-P6)/O6 -> 0.63721351 | AB6: =U6/O6 -> 0.28162651 | AC6: =AA6 -> 0.63721351
A7: 330 | B7: 2020 | C7: MNCN | D7: Media Nusantara Citra Tbk | E7: 9.4 | F7: Sub Sektor Advertising Printing dan Media | H7: 186000000000 | I7: 5781219000000 | J7: 18923235000000 | K7: 2302157000000 | L7: 4461328000000 | M7: 14461907000000 | N7: =5700000000+34300000000 -> 40000000000 | O7: 7956238000000 | P7: 3050672000000 | T7: =2085373000000+36220000000 -> 2121593000000 | U7: 1871028000000 | V7: =M7 -> 14461907000000 | W7: =L7/J7 -> 0.23575927 | X7: =L7/M7 -> 0.30848822 | Y7: =U7/J7 -> 0.098874637 | Z7: =U7/M7 -> 0.1293763 | AA7: =(O7-P7)/O7 -> 0.61656853 | AB7: =U7/O7 -> 0.23516491 | AC7: =AA7 -> 0.61656853
A8: 403 | B8: 2018 | C8: SCMA | D8: Surya Citra Media Tbk | E8: 9.4 | F8: Sub Sektor Advertising Printing dan Media | H8: =49777722000+101711857000 -> 151489579000 | I8: 1071441685000 | J8: 6589842943000 | K8: 218204415000 | L8: 1138592812000 | M8: 5451250131000 | N8: 58000000000 | O8: 5276794930000 | P8: =2358399763000+1069833225000 -> 3428232988000 | T8: =1069833225000+41960745000 -> 1111793970000 | U8: 1475042200000 | V8: =M8 -> 5451250131000 | W8: =L8/J8 -> 0.17277996 | X8: =L8/M8 -> 0.2088682 | Y8: =U8/J8 -> 0.22383571 | Z8: =U8/M8 -> 0.27058788 | AA8: =(O8-P8)/O8 -> 0.35031908 | AB8: =U8/O8 -> 0.27953374 | AC8: =AA8 -> 0.35031908
A9: 404 | B9: 2019 | C9: SCMA | D9: Surya Citra Media Tbk | E9: 9.4 | F9: Sub Sektor Advertising Printing dan Media | H9: =115471352000+17615430000 -> 133086782000 | I9: 1501728860000 | J9: 6716724073000 | K9: 239155397000 | L9: 1228125546000 | M9: 5488598527000 | N9: 58000000000 | O9: 5523362497000 | P9: =2862897768000+1177174576000 -> 4040072344000 | T9: =1177174576000+165730699000 -> 1342905275000 | U9: 1051164602000 | V9: =M9 -> 5488598527000 | W9: =L9/J9 -> 0.18284591 | X9: =L9/M9 -> 0.22375941 | Y9: =U9/J9 -> 0.1564996 | Z9: =U9/M9 -> 0.19151785 | AA9: =(O9-P9)/O9 -> 0.2685484 | AB9: =U9/O9 -> 0.19031244 | AC9: =AA9 -> 0.2685484
A10: 405 | B10: 2020 | C10: SCMA | D10: Surya Citra Media Tbk | E10: 9.4 | F10: Sub Sektor Advertising Printing dan Media | H10: =74618282000+45443124000 -> 120061406000 | I10: 1479438102000 | J10: 6766903494000 | K10: 1327841996000 | L10: 2870316946000 | M10: 3896586548000 | N10: 58000000000 | O10: 5101113259000 | P10: =2491631112000+1154111015000 -> 3645742127000 | T10: =1051164602000+1051164602000 -> 2102329204000 | U10: 1051164602000 | V10: =M10 -> 3896586548000 | W10: =L10/J10 -> 0.42416992 | X10: =L10/M10 -> 0.73662343 | Y10: =U10/J10 -> 0.15533909 | Z10: =U10/M10 -> 0.2697655 | AA10: =(O10-P10)/O10 -> 0.28530461 | AB10: =U10/O10 -> 0.20606572 | AC10: =AA10 -> 0.28530461
A11: 472 | B11: 2018 | C11: VIVA | D11: Visi Media Asia Tbk | E11: 9.4 | F11: Sub Sektor Advertising Printing dan Media | H11: 897825000 | I11: 801699400000 | J11: 8024565813000 | K11: 2949969316000 | L11: 6331144641000 | M11: 1692421172000 | N11: =38287370000+2069580000 -> 40356950000 | O11: 2400197838000 | P11: 2342825116000 | T11: =1332657089000+1144164032000 -> 2476821121000 | U11: -1111687862000 | V11: =M11 -> 1692421172000 | W11: =L11/J11 -> 0.78897037 | X11: =L11/M11 -> 3.7408801 | Y11: =U11/J11 -> -0.13853558 | Z11: =U11/M11 -> -0.65686242 | AA11: =(O11-P11)/O11 -> 0.02390333 | AB11: =U11/O11 -> -0.4631651 | AC11: =AA11 -> 0.02390333
A12: 473 | B12: 2019 | C12: VIVA | D12: Visi Media Asia Tbk | E12: 9.4 | F12: Sub Sektor Advertising Printing dan Media | I12: 755556286000 | J12: 8567653603000 | K12: 305874648000 | L12: 7419666167000 | M12: 1147987436000 | N12: =38287370000+2069580000 -> 40356950000 | O12: 2117781960000 | P12: 2149702385000 | T12: =1232204726000+473756432000 -> 1705961158000 | U12: -540883362000 | V12: =M12 -> 1147987436000 | W12: =L12/J12 -> 0.86600912 | X12: =L12/M12 -> 6.4631946 | Y12: =U12/J12 -> -0.063130863 | Z12: =U12/M12 -> -0.47115791 | AA12: =(O12-P12)/O12 -> -0.015072574 | AB12: =U12/O12 -> -0.25540087 | AC12: =AA12 -> -0.015072574
A13: 474 | B13: 2020 | C13: VIVA | D13: Visi Media Asia Tbk | E13: 9.4 | F13: Sub Sektor Advertising Printing dan Media | I13: 680914303000 | J13: 8584281930000 | K13: 459073171000 | L13: 8369846685000 | M13: 214435245000 | N13: =38287370000+2069580000 -> 40356950000 | O13: 1830516513000 | P13: 1780091859000 | T13: =1046289906000+828492869000 -> 1874782775000 | U13: -809081475000 | V13: =M13 -> 214435245000 | W13: =L13/J13 -> 0.97502001 | X13: =L13/M13 -> 39.032048 | Y13: =U13/J13 -> -0.094251503 | Z13: =U13/M13 -> -3.7730807 | AA13: =(O13-P13)/O13 -> 0.027546681 | AB13: =U13/O13 -> -0.44199627 | AC13: =AA13 -> 0.027546681
A14: 169 | B14: 2018 | C14: EMTK | D14: Elang Mahkota Teknologi Tbk | E14: 9.4 | F14: Sub Sektor Advertising, Printing dan Media | H14: =753122507000+1890135227000 -> 2643257734000 | I14: 2518586345000 | J14: 19525411684000 | K14: 1788053654000 | L14: 4061078369000 | M14: 15464333315000 | N14: 12567018000 | O14: 8959710884000 | P14: 6125120967000 | T14: =496501244000+2446991687000 -> 2943492931000 | U14: -2305536736000 | V14: =M14 -> 15464333315000 | W14: =L14/J14 -> 0.20798939 | X14: =L14/M14 -> 0.26260934 | Y14: =U14/J14 -> -0.11807878 | Z14: =U14/M14 -> -0.14908737 | AA14: =(O14-P14)/O14 -> 0.31637069 | AB14: =U14/O14 -> -0.25732267 | AC14: =AA14 -> 0.31637069 | AD14: 1574090526000 | AE14: 116849247000 | AI14: 1684548534000 | AK14: 28802899000 | AM14: 431375436000
A15: 170 | B15: 2019 | C15: EMTK | D15: Elang Mahkota Teknologi Tbk | E15: 9.4 | F15: Sub Sektor Advertising, Printing dan Media | H15: =780818591000+1274019829000 -> 2054838420000 | I15: 3028963325000 | J15: 17540637852000 | K15: 2586055335000 | L15: 5275358414000 | M15: 12265279438000 | N15: 12567018000 | O15: 11030044792000 | P15: 8270027096000 | T15: =1745999135000+2607161189000 -> 4353160324000 | U15: -2343106373000 | V15: =M15 -> 12265279438000 | W15: =L15/J15 -> 0.30075066 | X15: =L15/M15 -> 0.43010503 | Y15: =U15/J15 -> -0.13358159 | Z15: =U15/M15 -> -0.19103571 | AA15: =(O15-P15)/O15 -> 0.25022724 | AB15: =U15/O15 -> -0.21242945 | AC15: =AA15 -> 0.25022724 | AD15: 1497930720000 | AE15: 81273105000 | AI15: -528157639000 | AK15: 12280970000 | AM15: 56439826000
A16: 171 | B16: 2020 | C16: EMTK | D16: Elang Mahkota Teknologi Tbk | E16: 9.4 | F16: Sub Sektor Advertising, Printing dan Media | H16: =997476863000+1305584490000 -> 2303061353000 | I16: 4583995711000 | J16: 17884145634000 | K16: 2620257556000 | L16: 5485106483000 | M16: 12399039151000 | N16: 12567018000 | O16: 11936381982000 | P16: 9043072852000 | T16: =88249012000+1579745270000 -> 1667994282000 | U16: -1717376472000 | V16: =M16 -> 12399039151000 | W16: =L16/J16 -> 0.30670218 | X16: =L16/M16 -> 0.44238158 | Y16: =U16/J16 -> -0.096027873 | Z16: =U16/M16 -> -0.13850884 | AA16: =(O16-P16)/O16 -> 0.24239415 | AB16: =U16/O16 -> -0.14387747 | AC16: =AA16 -> 0.24239415 | AD16: 1521248746000 | AE16: 81267689000 | AI16: 0 | AK16: 9361613000 | AM16: 41008261000
A17: 259 | B17: 2018 | C17: JTPE | D17: Jasuindo Tiga Perkasa Tbk | E17: 9.4 | F17: Sub Sektor Advertising, Printing dan Media | H17: 8944733876 | I17: 437901244110 | J17: 1087169297635 | K17: 42310284440 | L17: 439743355312 | M17: 647425942323 | N17: 6850000000 | O17: 1269759234189 | P17: 991874760024 | T17: =40386642833+70097895345 -> 110484538178 | U17: 120550064804 | V17: =M17 -> 647425942323 | W17: =L17/J17 -> 0.40448471 | X17: =L17/M17 -> 0.679218 | Y17: =U17/J17 -> 0.11088435 | Z17: =U17/M17 -> 0.186199 | AA17: =(O17-P17)/O17 -> 0.21884816 | AB17: =U17/O17 -> 0.094939309 | AC17: =AA17 -> 0.21884816
A18: 260 | B18: 2019 | C18: JTPE | D18: Jasuindo Tiga Perkasa Tbk | E18: 9.4 | F18: Sub Sektor Advertising, Printing dan Media | H18: 9967624124 | I18: 501238262227 | J18: 1152696526641 | K18: 29176627515 | L18: 406866280932 | M18: 745830245709 | N18: 6850000000 | O18: 1438183885309 | P18: 1058393016361 | T18: =41198223065+82378805407 -> 123577028472 | U18: 182442649410 | V18: =M18 -> 745830245709 | W18: =L18/J18 -> 0.35296912 | X18: =L18/M18 -> 0.54552129 | Y18: =U18/J18 -> 0.15827466 | Z18: =U18/M18 -> 0.24461686 | AA18: =(O18-P18)/O18 -> 0.26407671 | AB18: =U18/O18 -> 0.12685627 | AC18: =AA18 -> 0.26407671
A19: 261 | B19: 2020 | C19: JTPE | D19: Jasuindo Tiga Perkasa Tbk | E19: 9.4 | F19: Sub Sektor Advertising, Printing dan Media | H19: 1637359473 | I19: 510514957020 | J19: 1038097010616 | K19: 23715199115 | L19: 267681176266 | M19: 770415834350 | N19: 6850000000 | O19: 978625887145 | P19: 758926697868 | T19: =27076217248+79701637171 -> 106777854419 | U19: 74172914384 | V19: =M19 -> 770415834350 | W19: =L19/J19 -> 0.25785757 | X19: =L19/M19 -> 0.34745025 | Y19: =U19/J19 -> 0.071450851 | Z19: =U19/M19 -> 0.096276467 | AA19: =(O19-P19)/O19 -> 0.22449763 | AB19: =U19/O19 -> 0.075792921 | AC19: =AA19 -> 0.22449763
A20: 31 | B20: 2018 | C20: ASBI | D20: Asuransi Bintang Tbk | E20: 8.4 | F20: Sub Sektor Asuransi | H20: =x!C12 -> 290476830 | I20: 123308301000 | J20: 874472888000 | L20: 593110979000 | M20: 281361909000 | N20: 640000000 | O20: 264899142000 | P20: 124758053000 | T20: 3501669000 | U20: 3274307000 | V20: =M20 -> 281361909000 | W20: =L20/J20 -> 0.67824971 | X20: =L20/M20 -> 2.1080003 | Y20: =U20/J20 -> 0.0037443208 | Z20: =U20/M20 -> 0.01163735 | AA20: =(O20-P20)/O20 -> 0.52903565 | AB20: =U20/O20 -> 0.01236058 | AC20: =AA20 -> 0.52903565 | AE20: 1914136000 | AI20: 4929704000 | AL20: 365466000 | AM20: 37472681000
A21: 32 | B21: 2019 | C21: ASBI | D21: Asuransi Bintang Tbk | E21: 8.4 | F21: Sub Sektor Asuransi | H21: =x!B12 -> 272057904 | I21: 127895603000 | J21: 857520585000 | L21: 566035087000 | M21: 291351494000 | N21: 640000000 | O21: 250804486000 | P21: 134257087000 | T21: 1102516000 | U21: 3581215000 | V21: =M21 -> 291351494000 | W21: =L21/J21 -> 0.66008338 | X21: =L21/M21 -> 1.9427911 | Y21: =U21/J21 -> 0.0041762438 | Z21: =U21/M21 -> 0.012291734 | AA21: =(O21-P21)/O21 -> 0.46469424 | AB21: =U21/O21 -> 0.014278911 | AC21: =AA21 -> 0.46469424 | AE21: 891342000 | AI21: 4929704000 | AL21: 259575000 | AM21: 24208733000
A22: 33 | B22: 2020 | C22: ASBI | D22: Asuransi Bintang Tbk | E22: 8.4 | F22: Sub Sektor Asuransi | H22: =x!A12 -> 304792271 | I22: 125064327000 | J22: 871769183000 | L22: 557997452000 | M22: 313771731000 | N22: 640000000 | O22: 231470118000 | P22: 109895092000 | T22: =780141000+425091000 -> 1205232000 | U22: 10456654000 | V22: =M22 -> 313771731000 | W22: =L22/J22 -> 0.64007476 | X22: =L22/M22 -> 1.7783548 | Y22: =U22/J22 -> 0.011994751 | Z22: =U22/M22 -> 0.033325673 | AA22: =(O22-P22)/O22 -> 0.5252299 | AB22: =U22/O22 -> 0.045174963 | AC22: =AA22 -> 0.5252299 | AE22: 207838000 | AI22: 4929704000 | AL22: 418733000 | AM22: 46947329000
A23: 37 | B23: 2018 | C23: ASMI | D23: Asuransi Kresna Mitra Tbk | E23: 8.4 | F23: Sub Sektor Asuransi | H23: 229934584995 | I23: 21609167523 | J23: 969866560976 | L23: 450272263738 | M23: 519594297238 | N23: 25000000000 | O23: 135633770098 | P23: 68591523905 | T23: 76025853817 | U23: 71761034881 | V23: =M23 -> 519594297238 | W23: =L23/J23 -> 0.46426208 | X23: =L23/M23 -> 0.86658431 | Y23: =U23/J23 -> 0.073990627 | Z23: =U23/M23 -> 0.13810974 | AA23: =(O23-P23)/O23 -> 0.49428875 | AB23: =U23/O23 -> 0.52907941 | AC23: =AA23 -> 0.49428875 | AE23: 1284135515 | AK23: 1378488571 | AM23: 19174178788
A24: 38 | B24: 2019 | C24: ASMI | D24: Asuransi Kresna Mitra Tbk | E24: 8.4 | F24: Sub Sektor Asuransi | H24: 351654846593 | I24: 24621076327 | J24: 975687462693 | L24: 445392630259 | M24: 530294832434 | N24: 25000000000 | O24: 175174507884 | P24: 101954815930 | T24: 72793612247 | U24: 8260755476 | V24: =M24 -> 530294832434 | W24: =L24/J24 -> 0.45649109 | X24: =L24/M24 -> 0.83989623 | Y24: =U24/J24 -> 0.0084666 | Z24: =U24/M24 -> 0.015577665 | AA24: =(O24-P24)/O24 -> 0.41798143 | AB24: =U24/O24 -> 0.047157292 | AC24: =AA24 -> 0.41798143 | AE24: 1219335058 | AK24: 1891162306 | AM24: 9580544598
A25: 39 | B25: 2020 | C25: ASMI | D25: Asuransi Kresna Mitra Tbk | E25: 8.4 | F25: Sub Sektor Asuransi | H25: 299816222397 | I25: 23989286699 | J25: 990991744064 | L25: 547541424689 | M25: 443450319375 | N25: 25000000000 | O25: 185567699856 | P25: 179184782942 | T25: 91760615438 | U25: -88526593736 | V25: =M25 -> 443450319375 | W25: =L25/J25 -> 0.55251865 | X25: =L25/M25 -> 1.23473 | Y25: =U25/J25 -> -0.089331313 | Z25: =U25/M25 -> -0.19963137 | AA25: =(O25-P25)/O25 -> 0.034396702 | AB25: =U25/O25 -> -0.4770582 | AC25: =AA25 -> 0.034396702 | AE25: 1078815684 | AK25: 1285504951 | AM25: 10945430380
A26: 40 | B26: 2018 | C26: ASRM | D26: Asuransi Ramayana Tbk | E26: 8.4 | F26: Sub Sektor Asuransi | H26: 405170089601 | I26: 59951428986 | J26: 1478007061719 | L26: 1072221723281 | M26: 405785338438 | N26: 420000000 | O26: 902165344517 | P26: 590399043504 | T26: 31849926816 | U26: 3573526494 | V26: =M26 -> 405785338438 | W26: =L26/J26 -> 0.72545102 | X26: =L26/M26 -> 2.6423373 | Y26: =U26/J26 -> 0.0024178007 | Z26: =U26/M26 -> 0.0088064456 | AA26: =(O26-P26)/O26 -> 0.34557557 | AB26: =U26/O26 -> 0.0039610549 | AC26: =AA26 -> 0.34557557 | AL26: 98816860220 | AM26: 32885830555
A27: 41 | B27: 2019 | C27: ASRM | D27: Asuransi Ramayana Tbk | E27: 8.4 | F27: Sub Sektor Asuransi | H27: 386940712793 | I27: 67512713635 | J27: 1548001829554 | L27: 1104712550189 | M27: 443289279365 | N27: 420000000 | O27: 1177500392010 | P27: 842624761795 | T27: 40486294000 | U27: 2089220151 | V27: =M27 -> 443289279365 | W27: =L27/J27 -> 0.71363775 | X27: =L27/M27 -> 2.4920805 | Y27: =U27/J27 -> 0.0013496238 | Z27: =U27/M27 -> 0.004712995 | AA27: =(O27-P27)/O27 -> 0.28439534 | AB27: =U27/O27 -> 0.001774284 | AC27: =AA27 -> 0.28439534 | AL27: 40172672851 | AM27: 58790710807
A28: 42 | B28: 2020 | C28: ASRM | D28: Asuransi Ramayana Tbk | E28: 8.4 | F28: Sub Sektor Asuransi | H28: 381002504552 | I28: 65757265183 | J28: 1516562973028 | L28: 1013381758085 | M28: 503181214943 | N28: 420000000 | O28: 1323139975825 | P28: 1014017867183 | T28: 25818453029 | U28: 16434884891 | V28: =M28 -> 503181214943 | W28: =L28/J28 -> 0.66820948 | X28: =L28/M28 -> 2.0139499 | Y28: =U28/J28 -> 0.010836929 | Z28: =U28/M28 -> 0.03266196 | AA28: =(O28-P28)/O28 -> 0.23362767 | AB28: =U28/O28 -> 0.012421123 | AC28: =AA28 -> 0.23362767 | AL28: 30381432048 | AM28: 63158641619
A29: 286 | B29: 2018 | C29: LPGI | D29: Lippo General Insurance Tbk | E29: 8.4 | F29: Sub Sektor Asuransi | H29: 1244581717689 | I29: 41712464138 | J29: 2485186649117 | L29: 1605367155250 | M29: 879819493867 | N29: 350000 | O29: 1132421357486 | P29: 1054327720740 | T29: 140384182320 | U29: 68687123783 | V29: =M29 -> 879819493867 | W29: =L29/J29 -> 0.64597448 | X29: =L29/M29 -> 1.8246551 | Y29: =U29/J29 -> 0.027638618 | Z29: =U29/M29 -> 0.078069563 | AA29: =(O29-P29)/O29 -> 0.068961642 | AB29: =U29/O29 -> 0.060655094 | AC29: =AA29 -> 0.068961642
A30: 287 | B30: 2019 | C30: LPGI | D30: Lippo General Insurance Tbk | E30: 8.4 | F30: Sub Sektor Asuransi | H30: 1185399911397 | I30: 59931111698 | J30: 2425843273596 | L30: 1575194310012 | M30: 848511733189 | N30: 350000 | O30: 1167490752228 | P30: 1079716721795 | T30: 190106898267 | U30: 80002543527 | V30: =M30 -> 848511733189 | W30: =L30/J30 -> 0.64933886 | X30: =L30/M30 -> 1.8564202 | Y30: =U30/J30 -> 0.032979271 | Z30: =U30/M30 -> 0.094285725 | AA30: =(O30-P30)/O30 -> 0.075181778 | AB30: =U30/O30 -> 0.068525205 | AC30: =AA30 -> 0.075181778
A31: 288 | B31: 2020 | C31: LPGI | D31: Lippo General Insurance Tbk | E31: 8.4 | F31: Sub Sektor Asuransi | H31: 1339253561392 | I31: 61211166120 | J31: 2815578393095 | L31: 1954498917680 | M31: 861079475415 | N31: 350000 | O31: 1220142637207 | P31: 1108228300836 | T31: 206201182748 | U31: 92908485040 | V31: =M31 -> 861079475415 | W31: =L31/J31 -> 0.69417315 | X31: =L31/M31 -> 2.2698241 | Y31: =U31/J31 -> 0.03299801 | Z31: =U31/M31 -> 0.10789769 | AA31: =(O31-P31)/O31 -> 0.091722339 | AB31: =U31/O31 -> 0.076145593 | AC31: =AA31 -> 0.091722339
A32: 334 | B32: 2018 | C32: MREI | D32: Maskapai Reasuransi Indonesia Tbk | E32: 8.4 | F32: Sub Sektor Asuransi | H32: =54966990708+829157926820+79259786000+3530551000+50555776200+147129560810+450308063 -> 1165050899601 | I32: 56864203151 | J32: 3426618296227 | L32: 2016141327384 | M32: 1410476968843 | N32: 1500000000 | O32: 1216973600364 | P32: 1045948505140 | T32: =94173689178 -> 94173689178 | U32: 140867155045 | V32: =M32 -> 1410476968843 | W32: =L32/J32 -> 0.5883764 | X32: =L32/M32 -> 1.4294039 | Y32: =U32/J32 -> 0.041109672 | Z32: =U32/M32 -> 0.099871999 | AA32: =(O32-P32)/O32 -> 0.14053312 | AB32: =U32/O32 -> 0.11575202 | AC32: =AA32 -> 0.14053312
A33: 335 | B33: 2019 | C33: MREI | D33: Maskapai Reasuransi Indonesia Tbk | E33: 8.4 | F33: Sub Sektor Asuransi | H33: =58470685750+824245247516+84426565660+116356935277+48742088000+51970033000+226867191437+85000000000+450308063 -> 1496529054703 | I33: 51455786161 | J33: 3915599148016 | L33: 2320512877462 | M33: 1595086270554 | N33: 1500000000 | O33: 1470949804896 | P33: 1309841112268 | T33: =95698788167+1430389202 -> 97129177369 | U33: 179282076899 | V33: =M33 -> 1595086270554 | W33: =L33/J33 -> 0.5926329 | X33: =L33/M33 -> 1.4547883 | Y33: =U33/J33 -> 0.045786627 | Z33: =U33/M33 -> 0.11239648 | AA33: =(O33-P33)/O33 -> 0.10952698 | AB33: =U33/O33 -> 0.12188185 | AC33: =AA33 -> 0.10952698
A34: 336 | B34: 2020 | C34: MREI | D34: Maskapai Reasuransi Indonesia Tbk | E34: 8.4 | F34: Sub Sektor Asuransi | H34: =62473445788+1346932585980+93783097120+101776975900+90999836000+53002907000+69729500572+85000000000+450308063 -> 1904148656423 | I34: 47281288654 | J34: 4203345266072 | L34: 2447545581054 | M34: 1755799685018 | N34: 1500000000 | O34: 1526256873467 | P34: 1437653868089 | T34: =87332688115+4793732040 -> 92126420155 | U34: 105182858790 | V34: =M34 -> 1755799685018 | W34: =L34/J34 -> 0.58228516 | X34: =L34/M34 -> 1.3939777 | Y34: =U34/J34 -> 0.025023607 | Z34: =U34/M34 -> 0.059905956 | AA34: =(O34-P34)/O34 -> 0.058052486 | AB34: =U34/O34 -> 0.068915568 | AC34: =AA34 -> 0.058052486
A35: 469 | B35: 2018 | C35: VINS | D35: Victoria Insurance Tbk | E35: 8.4 | F35: Sub Sektor Asuransi | H35: =8300000000+44396200000+17861250000+60822300000+16959102000+26178600000+3206244457+7374811915+90000000+3000751970 -> 188189260342 | I35: 1162886570 | J35: 262118630829 | L35: 82390315351 | M35: 179728315478 | N35: 4250000000 | O35: 25396161153 | P35: 13254779808 | T35: 13406900449 | U35: 3947657923 | V35: =W29:W38 -> 0.31432453 | W35: =L35/J35 -> 0.31432453 | X35: =L35/M35 -> 0.45841589 | Y35: =U34/J35 -> 0.4012796 | Z35: =U34/M35 -> 0.58523254 | AA35: =(O35-P35)/O35 -> 0.47807939 | AB35: =U34/O35 -> 4.1416834 | AC35: =AA35 -> 0.47807939
A36: 470 | B36: 2019 | C36: VINS | D36: Victoria Insurance Tbk | E36: 8.4 | F36: Sub Sektor Asuransi | H36: =38195050500+48523500000+66692600000+31599625000+951541661+3116108000 -> 189078425161 | I36: 2050262917 | J36: 284170955431 | L36: 97838690688 | M36: 186332264743 | N36: 4250000000 | O36: 26117484368 | P36: 11356539881 | T36: 15315108957 | U36: 21806030031 | V36: =M36 -> 186332264743 | W36: =L36/J36 -> 0.34429518 | X36: =L36/M36 -> 0.52507649 | Y36: =U36/J36 -> 0.076735604 | Z36: =U36/M36 -> 0.11702767 | AA36: =(O36-P36)/O36 -> 0.56517482 | AB36: =U36/O36 -> 0.83492077 | AC36: =AA36 -> 0.56517482
A37: 471 | B37: 2020 | C37: VINS | D37: Victoria Insurance Tbk | E37: 8.4 | F37: Sub Sektor Asuransi | H37: =27200000000+21361500000+81571880000+25341290000+20639947746+1995234258 -> 178109852004 | I37: 3518827068 | J37: 322342387320 | L37: 138095296876 | M37: 184247090444 | N37: 4250000000 | O37: 26509968632 | P37: 17239784399 | T37: 13577579905 | U37: 6211645756 | V37: =M37 -> 184247090444 | W37: =L37/J37 -> 0.42841185 | X37: =L37/M37 -> 0.74951141 | Y37: =U37/J37 -> 0.019270335 | Z37: =U37/M37 -> 0.033713671 | AA37: =(O37-P37)/O37 -> 0.34968673 | AB37: =U37/O37 -> 0.23431358 | AC37: =AA37 -> 0.34968673
A38: 13 | B38: 2018 | C38: AGRO | D38: Bank Rakyat Indonesia Agroniaga Tbk | E38: 8.1 | F38: Sub Sektor Bank | H38: 1931292672000 | I38: 259140701000 | J38: 23313671252000 | L38: 18889385436000 | M38: 4424285816000 | N38: 60000000000 | O38: 1663667161000 | P38: 987737580000 | T38: 281302960000 | U38: 142660203000 | V38: =M38 -> 4424285816000 | W38: =L38/J38 -> 0.81022784 | X38: =L38/M38 -> 4.2694768 | Y38: =U38/J38 -> 0.0061191651 | Z38: =U38/M38 -> 0.032244798 | AA38: =(O38-P38)/O38 -> 0.40628895 | AB38: =U38/O38 -> 0.085750447 | AC38: =AA38 -> 0.40628895 | AK38: 1988951000 | AL38: 611028000 | AM38: 12416420000
A39: 14 | B39: 2019 | C39: AGRO | D39: Bank Rakyat Indonesia Agroniaga Tbk | E39: 8.1 | F39: Sub Sektor Bank | H39: 3520204181000 | I39: 262120871000 | J39: 27067922912000 | L39: 22586218693000 | M39: 4481704219000 | N39: 60000000000 | O39: 2054837678000 | P39: 1361627112000 | T39: 312040493000 | U39: 86365196000 | V39: =M39 -> 4481704219000 | W39: =L39/J39 -> 0.83442748 | X39: =L39/M39 -> 5.0396496 | Y39: =U39/J39 -> 0.0031906843 | Z39: =U39/M39 -> 0.019270615 | AA39: =(O39-P39)/O39 -> 0.33735539 | AB39: =U39/O39 -> 0.042030179 | AC39: =AA39 -> 0.33735539 | AK39: 2133421000 | AL39: 811819000 | AM39: 14460082000
A40: 15 | B40: 2020 | C40: AGRO | D40: Bank Rakyat Indonesia Agroniaga Tbk | E40: 8.1 | F40: Sub Sektor Bank | H40: 3360741177000 | I40: 277438069000 | J40: 28015492262000 | L40: 23727802051000 | M40: 4287690211000 | N40: 60000000000 | O40: 1931524786000 | P40: 1306889194000 | T40: =115346440000+200473577000 -> 315820017000 | U40: 117206028000 | V40: =M40 -> 4287690211000 | W40: =L40/J40 -> 0.84695289 | X40: =L40/M40 -> 5.5339357 | Y40: =U40/J40 -> 0.0041836148 | Z40: =U40/M40 -> 0.02733547 | AA40: =(O40-P40)/O40 -> 0.32338989 | AB40: =U40/O40 -> 0.060680572 | AC40: =AA40 -> 0.32338989 | AK40: 1879511000 | AL40: 1043656000 | AM40: 10813540000
...

Sheet x
A2: Asuransi Bintang
A3: 100577266 | B3: 100874830 | C3: 114544426
A4: 618749 | B4: 437959 | C4: 450363
A5: 21646177 | B5: 23284126 | C5: 29624898
A6: 1528415 | B6: 1483648 | C6: 1664714
A7: 56925260 | B7: 55928711 | C7: 54076685
A8: 6729951 | B8: 6080793 | C8: 5486436
A9: 15450006 | B9: 16600424 | C9: 16490088
A10: 101219947 | B10: 67291213 | C10: 68072520
A11: 96500 | B11: 76200 | C11: 66700
A12: =SUM(A3:A11) -> 304792271 | B12: =SUM(B3:B11) -> 272057904 | C12: =SUM(C3:C11) -> 290476830
A14: Asuransi Ramayana
A16: 211605200000 | B16: 192475119000 | C16: 181937996190
A17: 4445786600 | B17: 3794412480 | C17: 4113860200
A18: 103519000000 | B18: 108236723800 | C18: 111934083010
A19: 50000000000 | B19: 50000000000 | C19: 50000000000
A20: 23582160000 | B20: 21982190044 | C20: 23833902641
A21: 9978743001 | B21: 8413067469 | C21: 7143462511
A22: 2039200000 | B22: 2039200000 | C22: 2039200000
A23: =SUM(A16:A22) -> 405170089601 | B23: =SUM(B16:B22) -> 386940712793 | C23: =SUM(C16:C22) -> 381002504552
A25: BANK QNB
A26: 3426305000000 | B26: 2653527000000
A27: 3332970000000 | B27: 989198000000
A28: =SUM(A26:A27) -> 6759275000000 | B28: =SUM(B26:B27) -> 3642725000000 | C28: =SUM(C26) -> 0
A30: BANK MANDIRI
A31: pendapatan | B31: beban
A32: 74454382000000 | B32: 23710628000000
A33: 6538188000000 | B33: 2659310000000
A34: 10342487000000 | B34: 7635354000000
A35: =SUM(A32,A33,A34) -> 91335057000000 | B35: =SUM(B34,B33,B32) -> 34005292000000
A37: 84431175000000 | B37: 29070226000000
A38: 7093915000000 | B38: 3014676000000
A39: 11113650000000 | B39: 9306147000000
A40: =SUM(A39,A38,A37) -> 102638740000000 | B40: =SUM(B39,B38,B37) -> 41391049000000
A42: 80093037000000 | B42: 28222605000000
A43: 7228080000000 | B43: 2590383000000
A44: 12890360000000 | B44: 11376645000000
A45: =SUM(A44,A43,A42) -> 100211477000000 | B45: =SUM(B44,B43,B42) -> 42189633000000
A47: BAKRIE
A48: 389948000000
...

Sheet banking-financial
A1: Tahun | B1: Kode | C1: Emiten | D1: Current Assets | E1: Fixed Assets | F1: Total Assets | G1: Current Liabilities | H1: Long-term Liabilities | I1: Total Liabilities | J1: Total Equity | K1: Outstanding shares | L1: Total Sales/Revenue | M1: COGS/COR | N1: Expenses | O1: Net Income | P1: Dividend | Q1: Price | R1: CR | S1: DER | T1: ROA | U1: ROE | V1: NPM | W1: DY | X1: DPR | Y1: PER | Z1: PBV | AA1: Industri
A2: 2018 | B2: ASBI | C2: Asuransi Bintang Tbk | D2: 673579165000 | E2: 123308301000 | F2: 874472888000 | I2: 593110979000 | J2: 281361909000 | K2: 640000000 | L2: 264899142000 | M2: 124758053000 | N2: 3501669000 | O2: 3274307000 | P2: 3658165000 | Q2: 250 | R2: =D2/I2 -> 1.1356714 | S2: =I2/J2 -> 2.1080003 | T2: =O2/F2 -> 0.0037443208 | U2: =O2/J2 -> 0.01163735 | V2: =O2/L2 -> 0.01236058 | W2: =(P2/K2)/Q2 -> 0.022863531 | X2: =P2/O2 -> 1.1172334 | Y2: =Q2/(O2/K2) -> 48.865302 | Z2: =Q2/(J2/K2) -> 0.56866262 | AA2: 1
A3: 2019 | B3: ASBI | C3: Asuransi Bintang Tbk | D3: 653613149000 | E3: 127895603000 | F3: 857520585000 | I3: 566035087000 | J3: 291351494000 | K3: 640000000 | L3: 250804486000 | M3: 134257087000 | N3: 1102516000 | O3: 3581215000 | P3: 3516989000 | Q3: 308 | R3: =D3/I3 -> 1.154722 | S3: =I3/J3 -> 1.9427911 | T3: =O3/F3 -> 0.0041762438 | U3: =O3/J3 -> 0.012291734 | V3: =O3/L3 -> 0.014278911 | W3: =(P3/K3)/Q3 -> 0.017841868 | X3: =P3/O3 -> 0.98206586 | Y3: =Q3/(O3/K3) -> 55.042772 | Z3: =Q3/(J3/K3) -> 0.6765711 | AA3: 1
A4: 2020 | B4: ASBI | C4: Asuransi Bintang Tbk | D4: 632468200000 | E4: 125064327000 | F4: 871769183000 | I4: 557997452000 | J4: 313771731000 | K4: 640000000 | L4: 231470118000 | M4: 109895092000 | N4: 1205232000 | O4: 10456654000 | P4: 2091802000 | Q4: 310 | R4: =D4/I4 -> 1.1334607 | S4: =I4/J4 -> 1.7783548 | T4: =O4/F4 -> 0.011994751 | U4: =O4/J4 -> 0.033325673 | V4: =O4/L4 -> 0.045174963 | W4: =(P4/K4)/Q4 -> 0.010543357 | X4: =P4/O4 -> 0.20004506 | Y4: =Q4/(O4/K4) -> 18.973565 | Z4: =Q4/(J4/K4) -> 0.6323068 | AA4: 1
A5: 2018 | B5: ASMI | C5: Asuransi Kresna Mitra Tbk | D5: 920102856747 | E5: 21609167523 | F5: 969866560976 | I5: 450272263738 | J5: 519594297238 | K5: 25000000000 | L5: 135633770098 | M5: 68591523905 | N5: 76025853817 | O5: 71761034881 | Q5: 700 | R5: =D5/I5 -> 2.0434367 | S5: =I5/J5 -> 0.86658431 | T5: =O5/F5 -> 0.073990627 | U5: =O5/J5 -> 0.13810974 | V5: =O5/L5 -> 0.52907941 | W5: =(P5/K5)/Q5 -> 0 | X5: =P5/O5 -> 0 | Y5: =Q5/(O5/K5) -> 243.86493 | Z5: =Q5/(J5/K5) -> 33.680123 | AA5: 1
A6: 2019 | B6: ASMI | C6: Asuransi Kresna Mitra Tbk | D6: 922123474882 | E6: 24621076327 | F6: 975687462693 | I6: 445392630259 | J6: 530294832434 | K6: 25000000000 | L6: 175174507884 | M6: 101954815930 | N6: 72793612247 | O6: 8260755476 | Q6: 1285 | R6: =D6/I6 -> 2.0703609 | S6: =I6/J6 -> 0.83989623 | T6: =O6/F6 -> 0.0084666 | U6: =O6/J6 -> 0.015577665 | V6: =O6/L6 -> 0.047157292 | W6: =(P6/K6)/Q6 -> 0 | X6: =P6/O6 -> 0 | Y6: =Q6/(O6/K6) -> 3888.8695 | Z6: =Q6/(J6/K6) -> 60.579508 | AA6: 1
A7: 2020 | B7: ASMI | C7: Asuransi Kresna Mitra Tbk | D7: 924782474882 | E7: 23989286699 | F7: 990991744064 | I7: 547541424689 | J7: 443450319375 | K7: 25000000000 | L7: 185567699856 | M7: 179184782942 | N7: 91760615438 | O7: -88526593736 | Q7: 990 | R7: =D7/I7 -> 1.6889726 | S7: =I7/J7 -> 1.23473 | T7: =O7/F7 -> -0.089331313 | U7: =O7/J7 -> -0.19963137 | V7: =O7/L7 -> -0.4770582 | W7: =(P7/K7)/Q7 -> 0 | X7: =P7/O7 -> 0 | Y7: =Q7/(O7/K7) -> -279.57701 | Z7: =Q7/(J7/K7) -> 55.81234 | AA7: 1
A8: 2018 | B8: ASRM | C8: Asuransi Ramayana Tbk | D8: 1210842541630 | E8: 59951428986 | F8: 1478007061719 | I8: 1072221723281 | J8: 405785338438 | K8: 420000000 | L8: 902165344517 | M8: 590399043504 | N8: 31849926816 | O8: 3573526494 | P8: 21297309695 | Q8: 2350 | R8: =D8/I8 -> 1.1292837 | S8: =I8/J8 -> 2.6423373 | T8: =O8/F8 -> 0.0024178007 | U8: =O8/J8 -> 0.0088064456 | V8: =O8/L8 -> 0.0039610549 | W8: =(P8/K8)/Q8 -> 0.021577821 | X8: =P8/O8 -> 5.9597459 | Y8: =Q8/(O8/K8) -> 276.19776 | Z8: =Q8/(J8/K8) -> 2.4323205 | AA8: 1
A9: 2019 | B9: ASRM | C9: Asuransi Ramayana Tbk | D9: 1254061746961 | E9: 67512713635 | F9: 1548001829554 | I9: 1104712550189 | J9: 443289279365 | K9: 420000000 | L9: 1177500392010 | M9: 842624761795 | N9: 40486294000 | O9: 2089220151 | P9: 18237550870 | Q9: 2010 | R9: =D9/I9 -> 1.1351928 | S9: =I9/J9 -> 2.4920805 | T9: =O9/F9 -> 0.0013496238 | U9: =O9/J9 -> 0.004712995 | V9: =O9/L9 -> 0.001774284 | W9: =(P9/K9)/Q9 -> 0.021603353 | X9: =P9/O9 -> 8.7293581 | Y9: =Q9/(O9/K9) -> 404.07422 | Z9: =Q9/(J9/K9) -> 1.9043998 | AA9: 1
A10: 2020 | B10: ASRM | C10: Asuransi Ramayana Tbk | D10: 1213949686630 | E10: 65757265183 | F10: 1516562973028 | I10: 1013381758085 | J10: 503181214943 | K10: 420000000 | L10: 1323139975825 | M10: 1014017867183 | N10: 25818453029 | O10: 16434884891 | P10: 16272822539 | Q10: 1680 | R10: =D10/I10 -> 1.1979194 | S10: =I10/J10 -> 2.0139499 | T10: =O10/F10 -> 0.010836929 | U10: =O10/J10 -> 0.03266196 | V10: =O10/L10 -> 0.012421123 | W10: =(P10/K10)/Q10 -> 0.02306239 | X10: =P10/O10 -> 0.99013912 | Y10: =Q10/(O10/K10) -> 42.933066 | Z10: =Q10/(J10/K10) -> 1.4022781 | AA10: 1
A11: 2018 | B11: LPGI | C11: Lippo General Insurance Tbk | D11: 2315732267904 | E11: 41712464138 | F11: 2485186649117 | I11: 1605367155250 | J11: 879819493867 | K11: 350000 | L11: 1132421357486 | M11: 1054327720740 | N11: 140384182320 | O11: 68687123783 | P11: 36732360000 | Q11: 4300 | R11: =D11/I11 -> 1.4424939 | S11: =I11/J11 -> 1.8246551 | T11: =O11/F11 -> 0.027638618 | U11: =O11/J11 -> 0.078069563 | V11: =O11/L11 -> 0.060655094 | W11: =(P11/K11)/Q11 -> 24.406884 | X11: =P11/O11 -> 0.53477796 | Y11: =Q11/(O11/K11) -> 0.021910948 | Z11: =Q11/(J11/K11) -> 0.0017105781 | AA11: 1
A12: 2019 | B12: LPGI | C12: Lippo General Insurance Tbk | D12: 2235292189141 | E12: 59931111698 | F12: 2425843273596 | I12: 1575194310012 | J12: 848511733189 | K12: 350000 | L12: 1167490752228 | M12: 1079716721795 | N12: 190106898267 | O12: 80002543527 | P12: 48726600000 | Q12: 3600 | R12: =D12/I12 -> 1.4190581 | S12: =I12/J12 -> 1.8564202 | T12: =O12/F12 -> 0.032979271 | U12: =O12/J12 -> 0.094285725 | V12: =O12/L12 -> 0.068525205 | W12: =(P12/K12)/Q12 -> 38.671905 | X12: =P12/O12 -> 0.60906314 | Y12: =Q12/(O12/K12) -> 0.015749499 | Z12: =Q12/(J12/K12) -> 0.0014849529 | AA12: 1
A13: 2020 | B13: LPGI | C13: Lippo General Insurance Tbk | D13: 2624614720238 | E13: 61211166120 | F13: 2815578393095 | I13: 1954498917680 | J13: 861079475415 | K13: 350000 | L13: 1220142637207 | M13: 1108228300836 | N13: 206201182748 | O13: 92908485040 | P13: 32084592000 | Q13: 3390 | R13: =D13/I13 -> 1.3428581 | S13: =I13/J13 -> 2.2698241 | T13: =O13/F13 -> 0.03299801 | U13: =O13/J13 -> 0.10789769 | V13: =O13/L13 -> 0.076145593 | W13: =(P13/K13)/Q13 -> 27.041375 | X13: =P13/O13 -> 0.34533543 | Y13: =Q13/(O13/K13) -> 0.012770631 | Z13: =Q13/(J13/K13) -> 0.0013779216 | AA13: 1
A14: 2018 | B14: MREI | C14: Maskapai Reasuransi Indonesia Tbk | D14: 2614558188655 | E14: 56864203151 | F14: 3426618296227 | I14: 2016141327384 | J14: 1410476968843 | K14: 1500000000 | L14: 1216973600364 | M14: 1045948505140 | N14: 94173689178 | O14: 140867155045 | P14: 28291292960 | Q14: 5100 | R14: =D14/I14 -> 1.296813 | S14: =I14/J14 -> 1.4294039 | T14: =O14/F14 -> 0.041109672 | U14: =O14/J14 -> 0.099871999 | V14: =O14/L14 -> 0.11575202 | W14: =(P14/K14)/Q14 -> 0.0036982082 | X14: =P14/O14 -> 0.20083669 | Y14: =Q14/(O14/K14) -> 54.306485 | Z14: =Q14/(J14/K14) -> 5.4236972 | AA14: 1
A15: 2019 | B15: MREI | C15: Maskapai Reasuransi Indonesia Tbk | D15: 3050314188997 | E15: 51455786161 | F15: 3915599148016 | I15: 2320512877462 | J15: 1595086270554 | K15: 1500000000 | L15: 1470949804896 | M15: 1309841112268 | N15: 97129177369 | O15: 179282076899 | P15: 25754804480 | Q15: 4280 | R15: =D15/I15 -> 1.3145 | S15: =I15/J15 -> 1.4547883 | T15: =O15/F15 -> 0.045786627 | U15: =O15/J15 -> 0.11239648 | V15: =O15/L15 -> 0.12188185 | W15: =(P15/K15)/Q15 -> 0.0040116518 | X15: =P15/O15 -> 0.14365521 | Y15: =Q15/(O15/K15) -> 35.809491 | Z15: =Q15/(J15/K15) -> 4.0248607 | AA15: 1
A16: 2020 | B16: MREI | C16: Maskapai Reasuransi Indonesia Tbk | D16: 3311255955993 | E16: 47281288654 | F16: 4203345266072 | I16: 2447545581054 | J16: 1755799685018 | K16: 1500000000 | L16: 1526256873467 | M16: 1437653868089 | N16: 92126420155 | O16: 105182858790 | P16: 25718451237 | Q16: 4700 | R16: =D16/I16 -> 1.3528884 | S16: =I16/J16 -> 1.3939777 | T16: =O16/F16 -> 0.025023607 | U16: =O16/J16 -> 0.059905956 | V16: =O16/L16 -> 0.068915568 | W16: =(P16/K16)/Q16 -> 0.0036480073 | X16: =P16/O16 -> 0.24451181 | Y16: =Q16/(O16/K16) -> 67.02613 | Z16: =Q16/(J16/K16) -> 4.0152644 | AA16: 1
A17: 2018 | B17: VINS | C17: Victoria Insurance Tbk | D17: 256222710742 | E17: 1162886570 | F17: 262118630829 | I17: 82390315351 | J17: 179728315478 | K17: 4250000000 | L17: 25396161153 | M17: 13254779808 | N17: 13406900449 | O17: 3947657923 | P17: 2325732322 | Q17: 126 | R17: =D17/I17 -> 3.1098644 | S17: =I17/J17 -> 0.45841589 | T17: =O17/F17 -> 0.015060577 | U17: =O17/J17 -> 0.021964585 | V17: =O17/L17 -> 0.1554431 | W17: =(P17/K17)/Q17 -> 0.0043431042 | X17: =P17/O17 -> 0.58914231 | Y17: =Q17/(O17/K17) -> 135.65005 | Z17: =Q17/(J17/K17) -> 2.9794971 | AA17: 1
A18: 2019 | B18: VINS | C18: Victoria Insurance Tbk | D18: 278787602299 | E18: 2050262917 | F18: 284170955431 | I18: 97838690688 | J18: 186332264743 | K18: 4250000000 | L18: 26117484368 | M18: 11356539881 | N18: 15315108957 | O18: 21806030031 | P18: 12646169490 | Q18: 123 | R18: =D18/I18 -> 2.8494617 | S18: =I18/J18 -> 0.52507649 | T18: =O18/F18 -> 0.076735604 | U18: =O18/J18 -> 0.11702767 | V18: =O18/L18 -> 0.83492077 | W18: =(P18/K18)/Q18 -> 0.02419162 | X18: =P18/O18 -> 0.5799391 | Y18: =Q18/(O18/K18) -> 23.972727 | Z18: =Q18/(J18/K18) -> 2.8054723 | AA18: 1
A19: 2020 | B19: VINS | C19: Victoria Insurance Tbk | D19: 317224915081 | E19: 3518827068 | F19: 322342387320 | I19: 138095296876 | J19: 184247090444 | K19: 4250000000 | L19: 26509968632 | M19: 17239784399 | N19: 13577579905 | O19: 6211645756 | P19: 13874395982 | Q19: 91 | R19: =D19/I19 -> 2.297145 | S19: =I19/J19 -> 0.74951141 | T19: =O19/F19 -> 0.019270335 | U19: =O19/J19 -> 0.033713671 | V19: =O19/L19 -> 0.23431358 | W19: =(P19/K19)/Q19 -> 0.035874327 | X19: =P19/O19 -> 2.2336103 | Y19: =Q19/(O19/K19) -> 62.262082 | Z19: =Q19/(J19/K19) -> 2.0990834 | AA19: 1
... A22: 2020 | B22: AGRO | C22: Bank Rakyat Indonesia Agroniaga Tbk | D22: 27536353583000 | E22: 277438069000 | F22: 28015492262000 | I22: 23727802051000 | J22: 4287690211000 | K22: 60000000000 | L22: 1931524786000 | M22: 1306889194000 | N22: 315820017000 | O22: 117206028000 | P22: 0 | Q22: 1035 | R22: =D22/I22 -> 1.1605101 | S22: =I22/J22 -> 5.5339357 | T22: =O22/F22 -> 0.0041836148 | U22: =O22/J22 -> 0.02733547 | V22: =O22/L22 -> 0.060680572 | W22: =(P22/K22)/Q22 -> 0 | X22: =P22/O22 -> 0 | Y22: =Q22/(O22/K22) -> 529.83623 | Z22: =Q22/(J22/K22) -> 14.483322 | AA22: 1
A23: 2018 | B23: AGRS | C23: Bank Agris Tbk | D23: 4035734000000 | E23: 15792000000 | F23: 4151151000000 | I23: 3618348000000 | J23: 532803000000 | K23: 11800000000 | L23: 133934000000 | M23: 171078000000 | N23: 171078000000 | O23: -31122000000 | Q23: 238 | R23: =D23/I23 -> 1.1153526 | S23: =I23/J23 -> 6.7911555 | T23: =O23/F23 -> -0.0074971978 | U23: =O23/J23 -> -0.058411833 | V23: =O23/L23 -> -0.23236818 | W23: =(P23/K23)/Q23 -> 0 | X23: =P23/O23 -> 0 | Y23: =Q23/(O23/K23) -> -90.238417 | Z23: =Q23/(J23/K23) -> 5.2709913 | AA23: 1
A24: 2019 | B24: AGRS | C24: Bank Agris Tbk | D24: 6083396000000 | E24: 134776000000 | F24: 6421844000000 | I24: 5219244000000 | J24: 1202600000000 | K24: 11800000000 | L24: 166231000000 | M24: 223544000000 | N24: 212614000000 | O24: -259525000000 | Q24: 135 | R24: =D24/I24 -> 1.1655703 | S24: =I24/J24 -> 4.3399667 | T24: =O24/F24 -> -0.040412847 | U24: =O24/J24 -> -0.21580326 | V24: =O24/L24 -> -1.5612311 | W24: =(P24/K24)/Q24 -> 0 | X24: =P24/O24 -> 0 | Y24: =Q24/(O24/K24) -> -6.138137 | Z24: =Q24/(J24/K24) -> 1.32463 | AA24: 1
A25: 2020 | B25: AGRS | C25: Bank Agris Tbk | D25: 7907292000000 | E25: 171496000000 | F25: 9854035000000 | I25: 7954197000000 | J25: 1899838000000 | K25: 11800000000 | L25: 169710000000 | M25: 336070000000 | N25: 336070000000 | O25: -176863000000 | Q25: 204 | R25: =D25/I25 -> 0.99410311 | S25: =I25/J25 -> 4.1867765 | T25: =O25/F25 -> -0.017948282 | U25: =O25/J25 -> -0.093093727 | V25: =O25/L25 -> -1.0421484 | W25: =(P25/K25)/Q25 -> 0 | X25: =P25/O25 -> 0 | Y25: =Q25/(O25/K25) -> -13.610535 | Z25: =Q25/(J25/K25) -> 1.2670554 | AA25: 1
A26: 2018 | B26: BABP | C26: Bank MNC Internasional Tbk | D26: 9968365000000 | E26: 48137000000 | F26: 10854855000000 | I26: 9424865000000 | J26: 1429990000000 | K26: 60000000000 | L26: 960256000000 | M26: 572785000000 | N26: 307274000000 | O26: 57021000000 | Q26: 50 | R26: =D26/I26 -> 1.0576666 | S26: =I26/J26 -> 6.5908608 | T26: =O26/F26 -> 0.0052530412 | U26: =O26/J26 -> 0.039875104 | V26: =O26/L26 -> 0.05938104 | W26: =(P26/K26)/Q26 -> 0 | X26: =P26/O26 -> 0 | Y26: =Q26/(O26/K26) -> 52.612196 | Z26: =Q26/(J26/K26) -> 2.0979168 | AA26: 1
A27: 2019 | B27: BABP | C27: Bank MNC Internasional Tbk | D27: 9281777000000 | E27: 48316000000 | F27: 10607879000000 | I27: 9048429000000 | J27: 1559450000000 | K27: 60000000000 | L27: 1071032000000 | M27: 667529000000 | N27: 339722000000 | O27: 20433000000 | Q27: 50 | R27: =D27/I27 -> 1.0257888 | S27: =I27/J27 -> 5.8023207 | T27: =O27/F27 -> 0.0019262098 | U27: =O27/J27 -> 0.013102696 | V27: =O27/L27 -> 0.019077861 | W27: =(P27/K27)/Q27 -> 0 | X27: =P27/O27 -> 0 | Y27: =Q27/(O27/K27) -> 146.82132 | Z27: =Q27/(J27/K27) -> 1.9237552 | AA27: 1
A28: 2020 | B28: BABP | C28: Bank MNC Internasional Tbk | D28: 102648350000000 | E28: 40914000000 | F28: 11652904000000 | I28: 10101667000000 | J28: 11652904000000 | K28: 60000000000 | L28: 969784000000 | M28: 368535000000 | N28: 345839000000 | O28: 10414000000 | Q28: 50 | R28: =D28/I28 -> 10.161526 | S28: =I28/J28 -> 0.86687979 | T28: =O28/F28 -> 0.00089368281 | U28: =O28/J28 -> 0.00089368281 | V28: =O28/L28 -> 0.010738474 | W28: =(P28/K28)/Q28 -> 0 | X28: =P28/O28 -> 0 | Y28: =Q28/(O28/K28) -> 288.07375 | Z28: =Q28/(J28/K28) -> 0.25744656 | AA28: 1
A29: 2018 | B29: BBCA | C29: Bank Central Asia Tbk | D29: 788261904000000 | E29: 19336901000000 | F29: 824787944000000 | I29: 668438779000000 | J29: 151753427000000 | K29: 88000000000 | L29: 56766800000000 | M29: 11476255000000 | N29: 27651554000000 | O29: 25851660000000 | P29: 6410302000000 | Q29: 26000 | R29: =D29/I29 -> 1.1792582 | S29: =I29/J29 -> 4.4047689 | T29: =O29/F29 -> 0.031343402 | U29: =O29/J29 -> 0.17035306 | V29: =O29/L29 -> 0.45540104 | W29: =(P29/K29)/Q29 -> 0.0028017054 | X29: =P29/O29 -> 0.24796481 | Y29: =Q29/(O29/K29) -> 88.504955 | Z29: =Q29/(J29/K29) -> 15.077089 | AA29: 1
A30: 2019 | B30: BBCA | C30: Bank Central Asia Tbk | D30: 878881370000000 | E30: 20852301000000 | F30: 918989312000000 | I30: 740067127000000 | J30: 174143156000000 | K30: 88000000000 | L30: 63837795000000 | M30: 13360347000000 | N30: 30742208000000 | O30: 28569974000000 | P30: 8752529000000 | Q30: 33425 | R30: =D30/I30 -> 1.1875698 | S30: =I30/J30 -> 4.2497629 | T30: =O30/F30 -> 0.031088473 | U30: =O30/J30 -> 0.16406027 | V30: =O30/L30 -> 0.44754011 | W30: =(P30/K30)/Q30 -> 0.0029756337 | X30: =P30/O30 -> 0.30635411 | Y30: =Q30/(O30/K30) -> 102.95424 | Z30: =Q30/(J30/K30) -> 16.890701 | AA30: 1
A31: 2020 | B31: BBCA | C31: Bank Central Asia Tbk | D31: 1.0305302e+15 | E31: 21915054000000 | F31: 1.0755703e+15 | I31: 885537919000000 | J31: 184714709000000 | K31: 88000000000 | L31: 65403161000000 | M31: 11241891000000 | N31: 29968715000000 | O31: 27147109000000 | P31: 13634221000000 | Q31: 33850 | R31: =D31/I31 -> 1.1637336 | S31: =I31/J31 -> 4.7940845 | T31: =O31/F31 -> 0.025239736 | U31: =O31/J31 -> 0.14696777 | V31: =O31/L31 -> 0.41507335 | W31: =(P31/K31)/Q31 -> 0.0045770851 | X31: =P31/O31 -> 0.50223473 | Y31: =Q31/(O31/K31) -> 109.72807 | Z31: =Q31/(J31/K31) -> 16.126491 | AA31: 1
A32: 2018 | B32: BBHI | C32: Bank Harda Internasional Tbk | D32: 2020118373285 | E32: 34368921424 | F32: 2264172563518 | I32: 1927690426617 | J32: 336482136901 | K32: 10000000000 | L32: 222339040371 | M32: 120624113372 | N32: 58187078926 | O32: -123143307728 | Q32: 171 | R32: =D32/I32 -> 1.0479475 | S32: =I32/J32 -> 5.7289532 | T32: =O32/F32 -> -0.054387775 | U32: =O32/J32 -> -0.36597279 | V32: =O32/L32 -> -0.55385373 | W32: =(P32/K32)/Q32 -> 0 | X32: =P32/O32 -> 0 | Y32: =Q32/(O32/K32) -> -13.88626 | Z32: =Q32/(J32/K32) -> 5.0819934 | AA32: 1
A33: 2019 | B33: BBHI | C33: Bank Harda Internasional Tbk | D33: 2287435487925 | E33: 32804430650 | F33: 2527173168770 | I33: 2227407291122 | J33: 299765877648 | K33: 10000000000 | L33: 222323923791 | M33: 135940003048 | N33: 60987155987 | O33: -36549663189 | Q33: 125 | R33: =D33/I33 -> 1.0269498 | S33: =I33/J33 -> 7.4304898 | T33: =O33/F33 -> -0.014462667 | U33: =O33/J33 -> -0.12192736 | V33: =O33/L33 -> -0.16439825 | W33: =(P33/K33)/Q33 -> 0 | X33: =P33/O33 -> 0 | Y33: =Q33/(O33/K33) -> -34.200042 | Z33: =Q33/(J33/K33) -> 4.1699209 | AA33: 1
A34: 2020 | B34: BBHI | C34: Bank Harda Internasional Tbk | D34: 2306058477913 | E34: 30376640192 | F34: 2586663487991 | I34: 2239597029811 | J34: 347066458180 | K34: 10000000000 | L34: 162125871157 | M34: 114535488869 | N34: 41188991154 | O34: 37011391337 | Q34: 424 | R34: =D34/I34 -> 1.0296756 | S34: =I34/J34 -> 6.4529342 | T34: =O34/F34 -> 0.014308545 | U34: =O34/J34 -> 0.10664065 | V34: =O34/L34 -> 0.228288 | W34: =(P34/K34)/Q34 -> 0 | X34: =P34/O34 -> 0 | Y34: =Q34/(O34/K34) -> 114.55932 | Z34: =Q34/(J34/K34) -> 12.21668 | AA34: 1
A35: 2018 | B35: BBKP | C35: Bank Bukopin Tbk | D35: 85349356000000 | E35: 3075041000000 | F35: 95643923000000 | I35: 87049486000000 | J35: 8594437000000 | K35: 22887540178 | L35: 7980892000000 | M35: 5387749000000 | N35: 2759809000000 | O35: 189970000000 | Q35: 272 | R35: =D35/I35 -> 0.98046938 | S35: =I35/J35 -> 10.128585 | T35: =O35/F35 -> 0.0019862213 | U35: =O35/J35 -> 0.022103833 | V35: =O35/L35 -> 0.023803104 | W35: =(P35/K35)/Q35 -> 0 | X35: =P35/O35 -> 0 | Y35: =Q35/(O35/K35) -> 32.770495 | Z35: =Q35/(J35/K35) -> 0.72435355 | AA35: 1
A36: 2019 | B36: BBKP | C36: Bank Bukopin Tbk | D36: 87668576000000 | E36: 3012215000000 | F36: 100264248000000 | I36: 91358763000000 | J36: 8905485000000 | K36: 22887540178 | L36: 7764858000000 | M36: 5750319000000 | N36: 2801776000000 | O36: 216749000000 | Q36: 224 | R36: =D36/I36 -> 0.95960774 | S36: =I36/J36 -> 10.258707 | T36: =O36/F36 -> 0.0021617775 | U36: =O36/J36 -> 0.02433882 | V36: =O36/L36 -> 0.027914097 | W36: =(P36/K36)/Q36 -> 0 | X36: =P36/O36 -> 0 | Y36: =Q36/(O36/K36) -> 23.653207 | Z36: =Q36/(J36/K36) -> 0.57569116 | AA36: 1
A37: 2020 | B37: BBKP | C37: Bank Bukopin Tbk | D37: 69019702000000 | E37: 3504403000000 | F37: 79938578000000 | I37: 71472136000000 | J37: 8466442000000 | K37: 22887540178 | L37: 5308366000000 | M37: 4756310000000 | N37: 2758323000000 | O37: -3258109000000 | Q37: 575 | R37: =D37/I37 -> 0.96568685 | S37: =I37/J37 -> 8.4418149 | T37: =O37/F37 -> -0.040757655 | U37: =O37/J37 -> -0.38482624 | V37: =O37/L37 -> -0.61376872 | W37: =(P37/K37)/Q37 -> 0 | X37: =P37/O37 -> 0 | Y37: =Q37/(O37/K37) -> -4.0392558 | Z37: =Q37/(J37/K37) -> 1.5544116 | AA37: 1
A38: 2018 | B38: BBMD | C38: Bank Mestika Dharma Tbk | D38: 11454704380759 | E38: 470415776572 | F38: 12093079368934 | I38: 9005066283473 | J38: 3088013085461 | K38: 10000000000 | L38: 1026137099056 | M38: 339167553637 | N38: 428776741954 | O38: 265862564725 | Q38: 1380 | R38: =D38/I38 -> 1.2720289 | S38: =I38/J38 -> 2.9161361 | T38: =O38/F38 -> 0.021984687 | U38: =O38/J38 -> 0.086095025 | V38: =O38/L38 -> 0.25909069 | W38: =(P38/K38)/Q38 -> 0 | X38: =P38/O38 -> 0 | Y38: =Q38/(O38/K38) -> 51.906518 | Z38: =Q38/(J38/K38) -> 4.468893 | AA38: 1
A39: 2019 | B39: BBMD | C39: Bank Mestika Dharma Tbk | D39: 12276512567406 | E39: 492662820097 | F39: 12900218775263 | I39: 9419749653807 | J39: 3480469121456 | K39: 10000000000 | L39: 1058536635511 | M39: 358086464478 | N39: 473384503657 | O39: 247573726183 | Q39: 2800 | R39: =D39/I39 -> 1.3032738 | S39: =I39/J39 -> 2.7064598 | T39: =O39/F39 -> 0.019191436 | U39: =O39/J39 -> 0.071132286 | V39: =O39/L39 -> 0.233883 | W39: =(P39/K39)/Q39 -> 0 | X39: =P39/O39 -> 0 | Y39: =Q39/(O39/K39) -> 113.09762 | Z39: =Q39/(J39/K39) -> 8.0448925 | AA39: 1
A40: 2020 | B40: BBMD | C40: Bank Mestika Dharma Tbk | D40: 13522482361051 | E40: 479822488029 | F40: 14159755232533 | I40: 10150492606994 | J40: 4009262625539 | K40: 10000000000 | L40: 1122202992204 | M40: 326616871157 | N40: 534878138389 | O40: 325932118524 | Q40: 1500 | R40: =D40/I40 -> 1.3321996 | S40: =I40/J40 -> 2.5317605 | T40: =O40/F40 -> 0.023018203 | U40: =O40/J40 -> 0.081294779 | V40: =O40/L40 -> 0.29043954 | W40: =(P40/K40)/Q40 -> 0 | X40: =P40/O40 -> 0 | Y40: =Q40/(O40/K40) -> 46.021853 | Z40: =Q40/(J40/K40) -> 3.7413364 | AA40: 1
A41: 2018 | B41: BBNP | C41: Bank Nusantara Parahyangan Tbk | Q41: 2200 | R41: =D41/I41 -> #DIV/0! | S41: =I41/J41 -> #DIV/0! | T41: =O41/F41 -> #DIV/0! | U41: =O41/J41 -> #DIV/0! | V41: =O41/L41 -> #DIV/0! | W41: =(P41/K41)/Q41 -> #DIV/0! | X41: =P41/O41 -> #DIV/0! | Y41: =Q41/(O41/K41) -> #DIV/0! | Z41: =Q41/(J41/K41) -> #DIV/0! | AA41: 1
A42: 2019 | B42: BBNP | C42: Bank Nusantara Parahyangan Tbk | Q42: 0 | R42: =D42/I42 -> #DIV/0! | S42: =I42/J42 -> #DIV/0! | T42: =O42/F42 -> #DIV/0! | U42: =O42/J42 -> #DIV/0! | V42: =O42/L42 -> #DIV/0! | W42: =(P42/K42)/Q42 -> #DIV/0! | X42: =P42/O42 -> #DIV/0! | Y42: =Q42/(O42/K42) -> #DIV/0! | Z42: =Q42/(J42/K42) -> #DIV/0! | AA42: 1
...

Sheet commodities
A1: Year | B1: Code | C1: Company Name | D1: Current Assets | E1: Fixed Assets | F1: Total Assets | G1: Current liabilities | H1: Long-Term Liabilities | I1: Total Liabilities | J1: Total Equity | K1: Total outstanding shares | L1: Total Sales/ Revenue | M1: COGS/ Cost of Revenues | N1: Expenses (Income) | O1: Net Income | P1: Dividend | Q1: Price | R1: CR | S1: DER | T1: ROA | U1: ROE | V1: NPM | W1: DY | X1: DPR | Y1: PER | Z1: PBV | AA1: Industri
A2: 2018 | B2: PGAS | C2: Perusahaan Gas Negara (Persero) Tbk | D2: 35820328250826 | E2: 41436061933356 | F2: 114968614731327 | G2: 23235117344046 | H2: 45366918001290 | I2: 68602035345336 | J2: 46366579385991 | K2: 70000000000 | L2: 56045332632978 | M2: 37082460251259 | N2: 10515185697510 | O2: 5280332435460 | P2: 796583982267 | Q2: 2130 | R2: =D2/G2 -> 1.5416461 | S2: =H2/J2 -> 0.97844004 | T2: =O2/F2 -> 0.045928469 | U2: =O2/J2 -> 0.11388229 | V2: =O2/L2 -> 0.094215382 | W2: =(P2/K2)/Q2 -> 0.0053426156 | X2: =P2/O2 -> 0.15085868 | Y2: =Q2/(O2/K2) -> 28.236859 | Z2: =Q2/(J2/K2) -> 3.2156782 | AA2: 2
A3: 2019 | B3: PGAS | C3: Perusahaan Gas Negara (Persero) Tbk | D3: 30852713195881 | E3: 38195772167402 | F3: 102501986581556 | G3: 15615845389597 | H3: 41926124645178 | I3: 57541970034775 | J3: 44960016546781 | K3: 70000000000 | L3: 53501024525284 | M3: 36439368501116 | N3: 10330208510406 | O3: 1570551591695 | P3: 1353577596878 | Q3: 2170 | R3: =D3/G3 -> 1.9757312 | S3: =H3/J3 -> 0.93252022 | T3: =O3/F3 -> 0.015322158 | U3: =O3/J3 -> 0.034932184 | V3: =O3/L3 -> 0.029355542 | W3: =(P3/K3)/Q3 -> 0.0089109783 | X3: =P3/O3 -> 0.86184854 | Y3: =Q3/(O3/K3) -> 96.717612 | Z3: =Q3/(J3/K3) -> 3.3785575 | AA3: 2
A4: 2020 | B4: PGAS | C4: Perusahaan Gas Negara (Persero) Tbk | D4: 28291608511530 | E4: 38050883273585 | F4: 106266878101475 | G4: 16688406014280 | H4: 47892007037420 | I4: 64580413051700 | J4: 41686465049775 | K4: 70000000000 | L4: 40700486761025 | M4: 28648929334025 | N4: 8359448650280 | O4: -2473389962225 | P4: 953146912445 | Q4: 1655 | R4: =D4/G4 -> 1.6952852 | S4: =H4/J4 -> 1.1488623 | T4: =O4/F4 -> -0.023275267 | U4: =O4/J4 -> -0.059333166 | V4: =O4/L4 -> -0.060770525 | W4: =(P4/K4)/Q4 -> 0.0082274226 | X4: =P4/O4 -> -0.38536055 | Y4: =Q4/(O4/K4) -> -46.83855 | Z4: =Q4/(J4/K4) -> 2.7790795 | AA4: 2
A5: 2018 | B5: RAJA | C5: Rukun Raharja Tbk | D5: 968326542522 | E5: 799069023234 | F5: 2767379051340 | G5: 258247232082 | H5: 601184420514 | I5: 859431652596 | J5: 1907947398744 | K5: 4227082500 | L5: 1710322585164 | M5: 1413357025509 | N5: 222397112736 | O5: 180054987318 | P5: 47384597871 | Q5: 472 | R5: =D5/G5 -> 3.7496105 | S5: =H5/J5 -> 0.31509486 | T5: =O5/F5 -> 0.065063363 | U5: =O5/J5 -> 0.094371044 | V5: =O5/L5 -> 0.10527545 | W5: =(P5/K5)/Q5 -> 0.0237495 | X5: =P5/O5 -> 0.26316737 | Y5: =Q5/(O5/K5) -> 11.080965 | Z5: =Q5/(J5/K5) -> 1.0457222 | AA5: 2
A6: 2019 | B6: RAJA | C6: Rukun Raharja Tbk | D6: 984042226112 | E6: 803461591434 | F6: 2508297621585 | G6: 326901962935 | H6: 475724956855 | I6: 802626919790 | J6: 1705670701795 | K6: 4227082500 | L6: 1697756320356 | M6: 1460057977986 | N6: 215576318772 | O6: 88096225202 | P6: 32799770926 | Q6: 189 | R6: =D6/G6 -> 3.0102059 | S6: =H6/J6 -> 0.27890786 | T6: =O6/F6 -> 0.035121919 | U6: =O6/J6 -> 0.051649023 | V6: =O6/L6 -> 0.051889794 | W6: =(P6/K6)/Q6 -> 0.04105521 | X6: =P6/O6 -> 0.37231755 | Y6: =Q6/(O6/K6) -> 9.068704 | Z6: =Q6/(J6/K6) -> 0.4683897 | AA6: 2
A7: 2020 | B7: RAJA | C7: Rukun Raharja Tbk | D7: 2350514170095 | E7: 745978102870 | F7: 2350514155990 | G7: 307596000530 | H7: 304525088140 | I7: 612121088670 | J7: 1738393081425 | K7: 4227082500 | L7: 1393076432020 | M7: 1166087107185 | N7: 44814815045 | O7: 85004671115 | P7: 27326152490 | Q7: 252 | R7: =D7/G7 -> 7.6415628 | S7: =H7/J7 -> 0.1751762 | T7: =O7/F7 -> 0.036164288 | U7: =O7/J7 -> 0.048898418 | V7: =O7/L7 -> 0.061019388 | W7: =(P7/K7)/Q7 -> 0.025652945 | X7: =P7/O7 -> 0.32146648 | Y7: =Q7/(O7/K7) -> 12.531368 | Z7: =Q7/(J7/K7) -> 0.61276405 | AA7: 2
A8: 2018 | B8: CTBN | C8: Citra Tubindo Tbk | D8: 2254015683477 | E8: 672401254464 | F8: 2254015683477 | G8: 714813569289 | H8: 109402434495 | I8: 824216003784 | J8: 1429799679693 | K8: 3200000000 | L8: 1239476562819 | M8: 1055003147262 | N8: 289740496401 | O8: 83913832674 | P8: 0 | Q8: 4300 | R8: =D8/G8 -> 3.1532917 | S8: =H8/J8 -> 0.076515918 | T8: =O8/F8 -> 0.037228593 | U8: =O8/J8 -> 0.058689223 | V8: =O8/L8 -> 0.067701024 | W8: =(P8/K8)/Q8 -> 0 | X8: =P8/O8 -> 0 | Y8: =Q8/(O8/K8) -> 163.97773 | Z8: =Q8/(J8/K8) -> 9.6237258 | AA8: 2
A9: 2019 | B9: CTBN | C9: Citra Tubindo Tbk | D9: 2395446398276 | E9: 617721642309 | F9: 2395446398276 | G9: 852416965550 | H9: 132771272903 | I9: 985188238453 | J9: 1410258159823 | K9: 3200000000 | L9: 1995615229813 | M9: 1631562719269 | N9: 314445540954 | O9: 22867965159 | P9: 252928695 | Q9: 3150 | R9: =D9/G9 -> 2.8101815 | S9: =H9/J9 -> 0.094146786 | T9: =O9/F9 -> 0.0095464316 | U9: =O9/J9 -> 0.016215446 | V9: =O9/L9 -> 0.011459105 | W9: =(P9/K9)/Q9 -> 2.5092132e-05 | X9: =P9/O9 -> 0.011060394 | Y9: =Q9/(O9/K9) -> 440.7913 | Z9: =Q9/(J9/K9) -> 7.1476275 | AA9: 2
A10: 2020 | B10: CTBN | C10: Citra Tubindo Tbk | D10: 1074198843445 | E10: 603761986100 | F10: 1839922465290 | G10: 321104528290 | H10: 117549095300 | I10: 438653623590 | J10: 1401268841700 | K10: 3200000000 | L10: 1779978175885 | M10: 1493795681105 | N10: 281118009900 | O10: -43122327885 | P10: 81061435 | Q10: 3220 | R10: =D10/G10 -> 3.3453245 | S10: =H10/J10 -> 0.083887611 | T10: =O10/F10 -> -0.023437035 | U10: =O10/J10 -> -0.030773772 | V10: =O10/L10 -> -0.024226324 | W10: =(P10/K10)/Q10 -> 7.8669871e-06 | X10: =P10/O10 -> -0.0018798019 | Y10: =Q10/(O10/K10) -> -238.94814 | Z10: =Q10/(J10/K10) -> 7.3533356 | AA10: 2
A11: 2018 | B11: ISSP | C11: Steel Pipe Industry of Indonesia Tbk | D11: 3640720000000 | E11: 2197050000000 | F11: 6494070000000 | G11: =I11-H11 -> 2579383000000 | H11: 999271000000 | I11: 3578654000000 | J11: 2915416000000 | K11: 17000000000 | L11: 4467590000000 | M11: 3935894000000 | N11: =110556000000+149591000000+257413000000+67212000000 -> 584772000000 | O11: 48741000000 | P11: 0 | Q11: 87 | R11: =D11/G11 -> 1.4114693 | S11: =H11/J11 -> 0.34275417 | T11: =O11/F11 -> 0.0075054627 | U11: =O11/J11 -> 0.016718369 | V11: =O11/L11 -> 0.010909909 | W11: =(P11/K11)/Q11 -> 0 | X11: =P11/O11 -> 0 | Y11: =Q11/(O11/K11) -> 30.344064 | Z11: =Q11/(J11/K11) -> 0.50730325 | AA11: 2
A12: 2019 | B12: ISSP | C12: Steel Pipe Industry of Indonesia Tbk | D12: 3547289000000 | E12: 2128844000000 | F12: 6424507000000 | G12: =I12-H12 -> 2542901000000 | H12: 782940000000 | I12: 3325841000000 | J12: 3098666000000 | K12: 17000000000 | L12: 4885875000000 | M12: 4197484000000 | N12: =149742000000+147856000000+261675000000+19267000000 -> 578540000000 | O12: 185694000000 | P12: 0 | Q12: 184 | R12: =D12/G12 -> 1.3949772 | S12: =H12/J12 -> 0.25267002 | T12: =O12/F12 -> 0.028904008 | U12: =O12/J12 -> 0.059927078 | V12: =O12/L12 -> 0.038006294 | W12: =(P12/K12)/Q12 -> 0 | X12: =P12/O12 -> 0 | Y12: =Q12/(O12/K12) -> 16.844917 | Z12: =Q12/(J12/K12) -> 1.0094667 | AA12: 2
A13: 2020 | B13: ISSP | C13: Steel Pipe Industry of Indonesia Tbk | D13: 3113612000000 | E13: 2197790000000 | F13: 6076604000000 | G13: =I13-H13 -> 2162323000000 | H13: 578941000000 | I13: 2741264000000 | J13: 3335340000000 | K13: 17000000000 | L13: 3775530000000 | M13: 3217408000000 | N13: =111101000000+130681000000+205664000000+27162000000 -> 474608000000 | O13: 175835000000 | P13: 0 | Q13: 160 | R13: =D13/G13 -> 1.4399384 | S13: =H13/J13 -> 0.17357781 | T13: =O13/F13 -> 0.028936393 | U13: =O13/J13 -> 0.052718763 | V13: =O13/L13 -> 0.046572269 | W13: =(P13/K13)/Q13 -> 0 | X13: =P13/O13 -> 0 | Y13: =Q13/(O13/K13) -> 15.469048 | Z13: =Q13/(J13/K13) -> 0.81550906 | AA13: 2
A14: 2018 | B14: NIKL | C14: Pelat Timah Nusantara Tbk | D14: 1633538255625 | E14: 438353322849 | F14: 2139961806972 | G14: 1485155286090 | H14: 31348266066 | I14: 1516503552156 | J14: 623458254816 | K14: 8000000000 | L14: 2362363017831 | M14: 2241184156263 | N14: 97572413241 | O14: -22261091022 | P14: 0 | Q14: 3500 | R14: =D14/G14 -> 1.0999107 | S14: =H14/J14 -> 0.050281259 | T14: =O14/F14 -> -0.010402565 | U14: =O14/J14 -> -0.035705824 | V14: =O14/L14 -> -0.0094232304 | W14: =(P14/K14)/Q14 -> 0 | X14: =P14/O14 -> 0 | Y14: =Q14/(O14/K14) -> -1257.8 | Z14: =Q14/(J14/K14) -> 44.910786 | AA14: 2
A15: 2019 | B15: NIKL | C15: Pelat Timah Nusantara Tbk | D15: 1635991007928 | E15: 405386814321 | F15: 2108628483178 | G15: 1437911697143 | H15: 36286808974 | I15: 1474198506117 | J15: 634429977061 | K15: 8000000000 | L15: 2267048602389 | M15: 2120573320557 | N15: 101630628030 | O15: 37263938066 | P15: 0 | Q15: 675 | R15: =D15/G15 -> 1.1377549 | S15: =H15/J15 -> 0.057195924 | T15: =O15/F15 -> 0.017672121 | U15: =O15/J15 -> 0.058736093 | V15: =O15/L15 -> 0.016437203 | W15: =(P15/K15)/Q15 -> 0 | X15: =P15/O15 -> 0 | Y15: =Q15/(O15/K15) -> 144.91222 | Z15: =Q15/(J15/K15) -> 8.5115776 | AA15: 2
A16: 2020 | B16: NIKL | C16: Pelat Timah Nusantara Tbk | D16: 1398292277655 | E16: 385936891340 | F16: 1860803648340 | G16: 1134888102530 | H16: 43444020620 | I16: 1178332123150 | J16: 682471525190 | K16: 8000000000 | L16: 2041413970050 | M16: 1903450256890 | N16: 100600541405 | O16: 38338476085 | P16: 0 | Q16: 1445 | R16: =D16/G16 -> 1.232097 | S16: =H16/J16 -> 0.063656899 | T16: =O16/F16 -> 0.020603182 | U16: =O16/J16 -> 0.056175935 | V16: =O16/L16 -> 0.018780354 | W16: =(P16/K16)/Q16 -> 0 | X16: =P16/O16 -> 0 | Y16: =Q16/(O16/K16) -> 301.52477 | Z16: =Q16/(J16/K16) -> 16.938436 | AA16: 2
A17: 2018 | B17: SRSN | C17: Indo Acidatama Tbk | D17: 448247260 | E17: 224257888000 | F17: 686777211000 | G17: =I17-H17 -> 182749220000 | H17: 26239975000 | I17: 208989195000 | J17: 477788016000 | K17: 12000000000 | L17: 600986872000 | M17: 458091261000 | N17: =83109088000+762203000 -> 83871291000 | O17: 38735092000 | P17: 0 | Q17: 66 | R17: =D17/G17 -> 0.0024527999 | S17: =H17/J17 -> 0.054919701 | T17: =O17/F17 -> 0.056401248 | U17: =O17/J17 -> 0.081071711 | V17: =O17/L17 -> 0.064452476 | W17: =(P17/K17)/Q17 -> 0 | X17: =P17/O17 -> 0 | Y17: =Q17/(O17/K17) -> 20.446576 | Z17: =Q17/(J17/K17) -> 1.6576389 | AA17: 2
A18: 2019 | B18: SRSN | C18: Indo Acidatama Tbk | D18: 537425364 | E18: 228818788000 | F18: 779246858000 | G18: =I18-H18 -> 217673718000 | H18: 46972577000 | I18: 264646295000 | J18: 514600563000 | K18: 12000000000 | L18: 684464392000 | M18: 511519472000 | N18: =102044774000+1425442000 -> 103470216000 | O18: 42829128000 | P18: 6017384000 | Q18: 68 | R18: =D18/G18 -> 0.0024689493 | S18: =H18/J18 -> 0.091279684 | T18: =O18/F18 -> 0.054962208 | U18: =O18/J18 -> 0.083227907 | V18: =O18/L18 -> 0.062573201 | W18: =(P18/K18)/Q18 -> 0.0073742451 | X18: =P18/O18 -> 0.14049747 | Y18: =Q18/(O18/K18) -> 19.052454 | Z18: =Q18/(J18/K18) -> 1.5856959 | AA18: 2
